Workbook

Sheet Sheet1
A1: Exercise 1.1 | B1: Goal Seek
A2: a. f(x)=x-x^(1/3)-2
A3: x | B3: f(x)
A4: 0 | B4: =A4-A4^(1/3)-2 -> -2
A5: =A4+0.1 -> 0.1 | B5: =A5-A5^(1/3)-2 -> -2.3641589
A6: =A5+0.1 -> 0.2 | B6: =A6-A6^(1/3)-2 -> -2.3848035
A7: =A6+0.1 -> 0.3 | B7: =A7-A7^(1/3)-2 -> -2.369433
A8: =A7+0.1 -> 0.4 | B8: =A8-A8^(1/3)-2 -> -2.3368063
A9: 3.521371 | B9: =A9-A9^(1/3)-2 -> -7.4141994e-06
A20: b. f(x)=x*tan(x)-1
A21: x | B21: f(x)
A22: 0 | B22: =A22*TAN(A22)-1 -> -1
A23: =A22+0.1 -> 0.1 | B23: =A23*TAN(A23)-1 -> -0.98996653
A24: =A23+0.1 -> 0.2 | B24: =A24*TAN(A24)-1 -> -0.95945799
A25: =A24+0.1 -> 0.3 | B25: =A25*TAN(A25)-1 -> -0.90719913
A26: =A25+0.1 -> 0.4 | B26: =A26*TAN(A26)-1 -> -0.83088271
A27: 0.86032028 | B27: =A27*TAN(A27)-1 -> -4.2380273e-05
A38: c. f(x)=(x^(4))-(e^(x))+1
A39: x | B39: f(x)
A40: 0 | B40: =A40^4-EXP(A40)+1 -> 0
A41: =A40+0.1 -> 0.1 | B41: =A41^4-EXP(A41)+1 -> -0.10507092
A42: =A41+0.1 -> 0.2 | B42: =A42^4-EXP(A42)+1 -> -0.21980276
A43: =A42+0.1 -> 0.3 | B43: =A43^4-EXP(A43)+1 -> -0.34175881
A44: =A43+0.1 -> 0.4 | B44: =A44^4-EXP(A44)+1 -> -0.4662247
A45: =A44+0.1 -> 0.5 | B45: =A45^4-EXP(A45)+1 -> -0.58622127
A46: =A45+0.1 -> 0.6 | B46: =A46^4-EXP(A46)+1 -> -0.6925188
A47: =A46+0.1 -> 0.7 | B47: =A47^4-EXP(A47)+1 -> -0.77365271
A48: =A47+0.1 -> 0.8 | B48: =A48^4-EXP(A48)+1 -> -0.81594093
A49: =A48+0.1 -> 0.9 | B49: =A49^4-EXP(A49)+1 -> -0.80350311
A50: =A49+0.1 -> 1 | B50: =A50^4-EXP(A50)+1 -> -0.71828183
A51: =A50+0.1 -> 1.1 | B51: =A51^4-EXP(A51)+1 -> -0.54006602
A52: =A51+0.1 -> 1.2 | B52: =A52^4-EXP(A52)+1 -> -0.24651692
A53: 1.2612668 | B53: =A53^4-EXP(A53)+1 -> 0.00073517274
A56: d. f(x)=(x^2)*(e^x)-1
A57: x | B57: f(x)
A58: 0 | B58: =A58^2*EXP(A58)-1 -> -1
A59: =A58+0.1 -> 0.1 | B59: =A59^2*EXP(A59)-1 -> -0.98894829
A60: =A59+0.1 -> 0.2 | B60: =A60^2*EXP(A60)-1 -> -0.95114389
A61: =A60+0.1 -> 0.3 | B61: =A61^2*EXP(A61)-1 -> -0.87851271
A62: =A61+0.1 -> 0.4 | B62: =A62^2*EXP(A62)-1 -> -0.76130805
...

Sheet Sheet2
A1: Exercise 1.2 | C1: Bi-Section Method
A2: a. f(x)=x-x^(1/3)-2
A3: x1 | B3: x2 | C3: f(x1) | D3: f(x2) | E3: x new | F3: f(x new)
A4: 3 | B4: 4 | C4: =A4-A4^(1/3)-2 -> -0.44224957 | D4: =B4-B4^(1/3)-2 -> 0.41259895 | E4: =(A4+B4)/2 -> 3.5 | F4: =E4-E4^(1/3)-2 -> -0.018294486
A5: =IF(C4*F4>0,E4,A4) -> 3.5 | B5: =IF(D4*F4>0,E4,B4) -> 4 | C5: =A5-A5^(1/3)-2 -> -0.018294486 | D5: =B5-B5^(1/3)-2 -> 0.41259895 | E5: =(A5+B5)/2 -> 3.75 | F5: =E5-E5^(1/3)-2 -> 0.19638375
A6: =IF(C5*F5>0,E5,A5) -> 3.5 | B6: =IF(D5*F5>0,E5,B5) -> 3.75 | C6: =A6-A6^(1/3)-2 -> -0.018294486 | D6: =B6-B6^(1/3)-2 -> 0.19638375 | E6: =(A6+B6)/2 -> 3.625 | F6: =E6-E6^(1/3)-2 -> 0.088841587
A7: =IF(C6*F6>0,E6,A6) -> 3.5 | B7: =IF(D6*F6>0,E6,B6) -> 3.625 | C7: =A7-A7^(1/3)-2 -> -0.018294486 | D7: =B7-B7^(1/3)-2 -> 0.088841587 | E7: =(A7+B7)/2 -> 3.5625 | F7: =E7-E7^(1/3)-2 -> 0.035221314
A8: =IF(C7*F7>0,E7,A7) -> 3.5 | B8: =IF(D7*F7>0,E7,B7) -> 3.5625 | C8: =A8-A8^(1/3)-2 -> -0.018294486 | D8: =B8-B8^(1/3)-2 -> 0.035221314 | E8: =(A8+B8)/2 -> 3.53125 | F8: =E8-E8^(1/3)-2 -> 0.0084501628
A9: =IF(C8*F8>0,E8,A8) -> 3.5 | B9: =IF(D8*F8>0,E8,B8) -> 3.53125 | C9: =A9-A9^(1/3)-2 -> -0.018294486 | D9: =B9-B9^(1/3)-2 -> 0.0084501628 | E9: =(A9+B9)/2 -> 3.515625 | F9: =E9-E9^(1/3)-2 -> -0.0049254989
A10: =IF(C9*F9>0,E9,A9) -> 3.515625 | B10: =IF(D9*F9>0,E9,B9) -> 3.53125 | C10: =A10-A10^(1/3)-2 -> -0.0049254989 | D10: =B10-B10^(1/3)-2 -> 0.0084501628 | E10: =(A10+B10)/2 -> 3.5234375 | F10: =E10-E10^(1/3)-2 -> 0.0017615007
A11: =IF(C10*F10>0,E10,A10) -> 3.515625 | B11: =IF(D10*F10>0,E10,B10) -> 3.5234375 | C11: =A11-A11^(1/3)-2 -> -0.0049254989 | D11: =B11-B11^(1/3)-2 -> 0.0017615007 | E11: =(A11+B11)/2 -> 3.5195312 | F11: =E11-E11^(1/3)-2 -> -0.0015822073
A12: =IF(C11*F11>0,E11,A11) -> 3.5195312 | B12: =IF(D11*F11>0,E11,B11) -> 3.5234375 | C12: =A12-A12^(1/3)-2 -> -0.0015822073 | D12: =B12-B12^(1/3)-2 -> 0.0017615007 | E12: =(A12+B12)/2 -> 3.5214844 | F12: =E12-E12^(1/3)-2 -> 8.9594701e-05
A14: b. f(x)=x*tan(x)-1
A15: x1 | B15: x2 | C15: f(x1) | D15: f(x2) | E15: x new | F15: f(x new)
A16: 0.5 | B16: 1 | C16: =A16*TAN(A16)-1 -> -0.72684876 | D16: =B16*TAN(B16)-1 -> 0.55740772 | E16: =(A16+B16)/2 -> 0.75 | F16: =E16*TAN(E16)-1 -> -0.30130266
A17: =IF(C16*F16>0,E16,A16) -> 0.75 | B17: =IF(D16*F16>0,E16,B16) -> 1 | C17: =A17*TAN(A17)-1 -> -0.30130266 | D17: =B17*TAN(B17)-1 -> 0.55740772 | E17: =(A17+B17)/2 -> 0.875 | F17: =E17*TAN(E17)-1 -> 0.047743926
A18: =IF(C17*F17>0,E17,A17) -> 0.75 | B18: =IF(D17*F17>0,E17,B17) -> 0.875 | C18: =A18*TAN(A18)-1 -> -0.30130266 | D18: =B18*TAN(B18)-1 -> 0.047743926 | E18: =(A18+B18)/2 -> 0.8125 | F18: =E18*TAN(E18)-1 -> -0.14222129
A19: =IF(C18*F18>0,E18,A18) -> 0.8125 | B19: =IF(D18*F18>0,E18,B18) -> 0.875 | C19: =A19*TAN(A19)-1 -> -0.14222129 | D19: =B19*TAN(B19)-1 -> 0.047743926 | E19: =(A19+B19)/2 -> 0.84375 | F19: =E19*TAN(E19)-1 -> -0.051553168
A20: =IF(C19*F19>0,E19,A19) -> 0.84375 | B20: =IF(D19*F19>0,E19,B19) -> 0.875 | C20: =A20*TAN(A20)-1 -> -0.051553168 | D20: =B20*TAN(B20)-1 -> 0.047743926 | E20: =(A20+B20)/2 -> 0.859375 | F20: =E20*TAN(E20)-1 -> -0.0030488034
A21: =IF(C20*F20>0,E20,A20) -> 0.859375 | B21: =IF(D20*F20>0,E20,B20) -> 0.875 | C21: =A21*TAN(A21)-1 -> -0.0030488034 | D21: =B21*TAN(B21)-1 -> 0.047743926 | E21: =(A21+B21)/2 -> 0.8671875 | F21: =E21*TAN(E21)-1 -> 0.022052678
A22: =IF(C21*F21>0,E21,A21) -> 0.859375 | B22: =IF(D21*F21>0,E21,B21) -> 0.8671875 | C22: =A22*TAN(A22)-1 -> -0.0030488034 | D22: =B22*TAN(B22)-1 -> 0.022052678 | E22: =(A22+B22)/2 -> 0.86328125 | F22: =E22*TAN(E22)-1 -> 0.0094293521
A23: =IF(C22*F22>0,E22,A22) -> 0.859375 | B23: =IF(D22*F22>0,E22,B22) -> 0.86328125 | C23: =A23*TAN(A23)-1 -> -0.0030488034 | D23: =B23*TAN(B23)-1 -> 0.0094293521 | E23: =(A23+B23)/2 -> 0.86132812 | F23: =E23*TAN(E23)-1 -> 0.0031722672
A24: =IF(C23*F23>0,E23,A23) -> 0.859375 | B24: =IF(D23*F23>0,E23,B23) -> 0.86132812 | C24: =A24*TAN(A24)-1 -> -0.0030488034 | D24: =B24*TAN(B24)-1 -> 0.0031722672 | E24: =(A24+B24)/2 -> 0.86035156 | F24: =E24*TAN(E24)-1 -> 5.7247293e-05
A25: =IF(C24*F24>0,E24,A24) -> 0.859375 | B25: =IF(D24*F24>0,E24,B24) -> 0.86035156 | C25: =A25*TAN(A25)-1 -> -0.0030488034 | D25: =B25*TAN(B25)-1 -> 5.7247293e-05 | E25: =(A25+B25)/2 -> 0.85986328 | F25: =E25*TAN(E25)-1 -> -0.0014968971
A27: c. f(x)=(x^4)-(e^x)+1
A28: x1 | B28: x2 | C28: f(x1) | D28: f(x2) | E28: x new | F28: f(x new)
A29: 1 | B29: 2 | C29: =A29^4-EXP(A29)+1 -> -0.71828183 | D29: =B29^4-EXP(B29)+1 -> 9.6109439 | E29: =(A29+B29)/2 -> 1.5 | F29: =E29^4-EXP(E29)+1 -> 1.5808109
A30: =IF(C29*F29>0,E29,A29) -> 1 | B30: =IF(D29*F29>0,E29,B29) -> 1.5 | C30: =A30^4-EXP(A30)+1 -> -0.71828183 | D30: =B30^4-EXP(B30)+1 -> 1.5808109 | E30: =(A30+B30)/2 -> 1.25 | F30: =E30^4-EXP(E30)+1 -> -0.048936707
A31: =IF(C30*F30>0,E30,A30) -> 1.25 | B31: =IF(D30*F30>0,E30,B30) -> 1.5 | C31: =A31^4-EXP(A31)+1 -> -0.048936707 | D31: =B31^4-EXP(B31)+1 -> 1.5808109 | E31: =(A31+B31)/2 -> 1.375 | F31: =E31^4-EXP(E31)+1 -> 0.61938617
A32: =IF(C31*F31>0,E31,A31) -> 1.25 | B32: =IF(D31*F31>0,E31,B31) -> 1.375 | C32: =A32^4-EXP(A32)+1 -> -0.048936707 | D32: =B32^4-EXP(B32)+1 -> 0.61938617 | E32: =(A32+B32)/2 -> 1.3125 | F32: =E32^4-EXP(E32)+1 -> 0.25209382
A33: =IF(C32*F32>0,E32,A32) -> 1.25 | B33: =IF(D32*F32>0,E32,B32) -> 1.3125 | C33: =A33^4-EXP(A33)+1 -> -0.048936707 | D33: =B33^4-EXP(B33)+1 -> 0.25209382 | E33: =(A33+B33)/2 -> 1.28125 | F33: =E33^4-EXP(E33)+1 -> 0.093717354
A34: =IF(C33*F33>0,E33,A33) -> 1.25 | B34: =IF(D33*F33>0,E33,B33) -> 1.28125 | C34: =A34^4-EXP(A34)+1 -> -0.048936707 | D34: =B34^4-EXP(B34)+1 -> 0.093717354 | E34: =(A34+B34)/2 -> 1.265625 | F34: =E34^4-EXP(E34)+1 -> 0.020476653
A35: =IF(C34*F34>0,E34,A34) -> 1.25 | B35: =IF(D34*F34>0,E34,B34) -> 1.265625 | C35: =A35^4-EXP(A35)+1 -> -0.048936707 | D35: =B35^4-EXP(B35)+1 -> 0.020476653 | E35: =(A35+B35)/2 -> 1.2578125 | F35: =E35^4-EXP(E35)+1 -> -0.014702058
A36: =IF(C35*F35>0,E35,A35) -> 1.2578125 | B36: =IF(D35*F35>0,E35,B35) -> 1.265625 | C36: =A36^4-EXP(A36)+1 -> -0.014702058 | D36: =B36^4-EXP(B36)+1 -> 0.020476653 | E36: =(A36+B36)/2 -> 1.2617188 | F36: =E36^4-EXP(E36)+1 -> 0.0027684944
A37: =IF(C36*F36>0,E36,A36) -> 1.2578125 | B37: =IF(D36*F36>0,E36,B36) -> 1.2617188 | C37: =A37^4-EXP(A37)+1 -> -0.014702058 | D37: =B37^4-EXP(B37)+1 -> 0.0027684944 | E37: =(A37+B37)/2 -> 1.2597656 | F37: =E37^4-EXP(E37)+1 -> -0.0059963828
A38: =IF(C37*F37>0,E37,A37) -> 1.2597656 | B38: =IF(D37*F37>0,E37,B37) -> 1.2617188 | C38: =A38^4-EXP(A38)+1 -> -0.0059963828 | D38: =B38^4-EXP(B38)+1 -> 0.0027684944 | E38: =(A38+B38)/2 -> 1.2607422 | F38: =E38^4-EXP(E38)+1 -> -0.0016213569
A39: =IF(C38*F38>0,E38,A38) -> 1.2607422 | B39: =IF(D38*F38>0,E38,B38) -> 1.2617188 | C39: =A39^4-EXP(A39)+1 -> -0.0016213569 | D39: =B39^4-EXP(B39)+1 -> 0.0027684944 | E39: =(A39+B39)/2 -> 1.2612305 | F39: =E39^4-EXP(E39)+1 -> 0.00057171401
A40: =IF(C39*F39>0,E39,A39) -> 1.2607422 | B40: =IF(D39*F39>0,E39,B39) -> 1.2612305 | C40: =A40^4-EXP(A40)+1 -> -0.0016213569 | D40: =B40^4-EXP(B40)+1 -> 0.00057171401 | E40: =(A40+B40)/2 -> 1.2609863 | F40: =E40^4-EXP(E40)+1 -> -0.00052528495
A41: =IF(C40*F40>0,E40,A40) -> 1.2609863 | B41: =IF(D40*F40>0,E40,B40) -> 1.2612305 | C41: =A41^4-EXP(A41)+1 -> -0.00052528495 | D41: =B41^4-EXP(B41)+1 -> 0.00057171401 | E41: =(A41+B41)/2 -> 1.2611084 | F41: =E41^4-EXP(E41)+1 -> 2.3098637e-05
A43: d. f(x)=(x^2)*(e^x)-1
...

Sheet Sheet3
A1: Exersice 1.3 | C1: Secant Method
A2: a. f(x)=x-x^(1/3)-2
A3: x1 | B3: x2 | C3: f(x1) | D3: f(x2) | E3: x3 | F3: f(x3)
A4: 3 | B4: 4 | C4: =Sheet3!A4-(Sheet3!A4^(1/3))-2 -> -0.44224957 | D4: =B4-(B4^(1/3))-2 -> 0.41259895 | E4: =A4-(C4/(C4-D4))*(A4-B4) -> 3.5173426 | F4: =E4-(E4^(1/3))-2 -> -0.003455471
A5: =B4 -> 4 | B5: =E4 -> 3.5173426 | C5: =Sheet3!A5-(Sheet3!A5^(1/3))-2 -> 0.41259895 | D5: =B5-(B5^(1/3))-2 -> -0.003455471 | E5: =A5-(C5/(C5-D5))*(A5-B5) -> 3.5213512 | F5: =E5-(E5^(1/3))-2 -> -2.4359805e-05
A6: =B5 -> 3.5173426 | B6: =E5 -> 3.5213512 | C6: =Sheet3!A6-(Sheet3!A6^(1/3))-2 -> -0.003455471 | D6: =B6-(B6^(1/3))-2 -> -2.4359805e-05 | E6: =A6-(C6/(C6-D6))*(A6-B6) -> 3.5213797 | F6: =E6-(E6^(1/3))-2 -> 1.5672987e-09
A7: =B6 -> 3.5213512 | B7: =E6 -> 3.5213797 | C7: =Sheet3!A7-(Sheet3!A7^(1/3))-2 -> -2.4359805e-05 | D7: =B7-(B7^(1/3))-2 -> 1.5672987e-09 | E7: =A7-(C7/(C7-D7))*(A7-B7) -> 3.5213797 | F7: =E7-(E7^(1/3))-2 -> 0
A8: =B7 -> 3.5213797 | B8: =E7 -> 3.5213797 | C8: =Sheet3!A8-(Sheet3!A8^(1/3))-2 -> 1.5672987e-09 | D8: =B8-(B8^(1/3))-2 -> 0 | E8: =A8-(C8/(C8-D8))*(A8-B8) -> 3.5213797 | F8: =E8-(E8^(1/3))-2 -> 0
A11: b. f(x)=x*tan(x)-1
A12: x1 | B12: x2 | C12: f(x1) | D12: f(x2) | E12: x3 | F12: f(x3)
A13: 0.5 | B13: 1 | C13: =Sheet3!A13*TAN(Sheet3!A13)-1 -> -0.72684876 | D13: =B13*TAN(B13)-1 -> 0.55740772 | E13: =A13-(C13/(C13-D13))*(A13-B13) -> 0.78298427 | F13: =E13*TAN(E13)-1 -> -0.22078673
A14: =B13 -> 1 | B14: =E13 -> 0.78298427 | C14: =Sheet3!A14*TAN(Sheet3!A14)-1 -> 0.55740772 | D14: =B14*TAN(B14)-1 -> -0.22078673 | E14: =A14-(C14/(C14-D14))*(A14-B14) -> 0.84455524 | F14: =E14*TAN(E14)-1 -> -0.049107219
A15: =B14 -> 0.78298427 | B15: =E14 -> 0.84455524 | C15: =Sheet3!A15*TAN(Sheet3!A15)-1 -> -0.22078673 | D15: =B15*TAN(B15)-1 -> -0.049107219 | E15: =A15-(C15/(C15-D15))*(A15-B15) -> 0.86216701 | F15: =E15*TAN(E15)-1 -> 0.0058553169
A16: =B15 -> 0.84455524 | B16: =E15 -> 0.86216701 | C16: =Sheet3!A16*TAN(Sheet3!A16)-1 -> -0.049107219 | D16: =B16*TAN(B16)-1 -> 0.0058553169 | E16: =A16-(C16/(C16-D16))*(A16-B16) -> 0.86029078 | F16: =E16*TAN(E16)-1 -> -0.00013634242
A17: =B16 -> 0.86216701 | B17: =E16 -> 0.86029078 | C17: =Sheet3!A17*TAN(Sheet3!A17)-1 -> 0.0058553169 | D17: =B17*TAN(B17)-1 -> -0.00013634242 | E17: =A17-(C17/(C17-D17))*(A17-B17) -> 0.86033347 | F17: =E17*TAN(E17)-1 -> -3.6894873e-07
A18: =B17 -> 0.86029078 | B18: =E17 -> 0.86033347 | C18: =Sheet3!A18*TAN(Sheet3!A18)-1 -> -0.00013634242 | D18: =B18*TAN(B18)-1 -> -3.6894873e-07 | E18: =A18-(C18/(C18-D18))*(A18-B18) -> 0.86033359 | F18: =E18*TAN(E18)-1 -> 2.3318236e-11
A19: =B18 -> 0.86033347 | B19: =E18 -> 0.86033359 | C19: =Sheet3!A19*TAN(Sheet3!A19)-1 -> -3.6894873e-07 | D19: =B19*TAN(B19)-1 -> 2.3318236e-11 | E19: =A19-(C19/(C19-D19))*(A19-B19) -> 0.86033359 | F19: =E19*TAN(E19)-1 -> 0
A20: =B19 -> 0.86033359 | B20: =E19 -> 0.86033359 | C20: =Sheet3!A20*TAN(Sheet3!A20)-1 -> 2.3318236e-11 | D20: =B20*TAN(B20)-1 -> 0 | E20: =A20-(C20/(C20-D20))*(A20-B20) -> 0.86033359 | F20: =E20*TAN(E20)-1 -> 0
A23: c. f(x)=(x^(4))-(e^(x))+1
A24: x1 | B24: x2 | C24: f(x1) | D24: f(x2) | E24: x3 | F24: f(x3)
A25: 1 | B25: 2 | C25: =(A25^4)-(EXP(A25))+1 -> -0.71828183 | D25: =(B25^4)-(EXP(B25))+1 -> 9.6109439 | E25: =A25-(C25/(C25-D25))*(A25-B25) -> 1.0695388 | F25: =E25^4-EXP(E25)+1 -> -0.60549775
A26: =B25 -> 2 | B26: =E25 -> 1.0695388 | C26: =(A26^4)-(EXP(A26))+1 -> 9.6109439 | D26: =(B26^4)-(EXP(B26))+1 -> -0.60549775 | E26: =A26-(C26/(C26-D26))*(A26-B26) -> 1.1246844 | F26: =E26^4-EXP(E26)+1 -> -0.47923487
A27: =B26 -> 1.0695388 | B27: =E26 -> 1.1246844 | C27: =(A27^4)-(EXP(A27))+1 -> -0.60549775 | D27: =(B27^4)-(EXP(B27))+1 -> -0.47923487 | E27: =A27-(C27/(C27-D27))*(A27-B27) -> 1.3339915 | F27: =E27^4-EXP(E27)+1 -> 0.37057313
A28: =B27 -> 1.1246844 | B28: =E27 -> 1.3339915 | C28: =(A28^4)-(EXP(A28))+1 -> -0.47923487 | D28: =(B28^4)-(EXP(B28))+1 -> 0.37057313 | E28: =A28-(C28/(C28-D28))*(A28-B28) -> 1.2427196 | F28: =E28^4-EXP(E28)+1 -> -0.080001023
A29: =B28 -> 1.3339915 | B29: =E28 -> 1.2427196 | C29: =(A29^4)-(EXP(A29))+1 -> 0.37057313 | D29: =(B29^4)-(EXP(B29))+1 -> -0.080001023 | E29: =A29-(C29/(C29-D29))*(A29-B29) -> 1.2589252 | F29: =E29^4-EXP(E29)+1 -> -0.0097494651
A30: =B29 -> 1.2427196 | B30: =E29 -> 1.2589252 | C30: =(A30^4)-(EXP(A30))+1 -> -0.080001023 | D30: =(B30^4)-(EXP(B30))+1 -> -0.0097494651 | E30: =A30-(C30/(C30-D30))*(A30-B30) -> 1.2611743 | F30: =E30^4-EXP(E30)+1 -> 0.0003190317
A31: =B30 -> 1.2589252 | B31: =E30 -> 1.2611743 | C31: =(A31^4)-(EXP(A31))+1 -> -0.0097494651 | D31: =(B31^4)-(EXP(B31))+1 -> 0.0003190317 | E31: =A31-(C31/(C31-D31))*(A31-B31) -> 1.261103 | F31: =E31^4-EXP(E31)+1 -> -1.2055644e-06
A32: =B31 -> 1.2611743 | B32: =E31 -> 1.261103 | C32: =(A32^4)-(EXP(A32))+1 -> 0.0003190317 | D32: =(B32^4)-(EXP(B32))+1 -> -1.2055644e-06 | E32: =A32-(C32/(C32-D32))*(A32-B32) -> 1.2611033 | F32: =E32^4-EXP(E32)+1 -> -1.481375e-10
A33: =B32 -> 1.261103 | B33: =E32 -> 1.2611033 | C33: =(A33^4)-(EXP(A33))+1 -> -1.2055644e-06 | D33: =(B33^4)-(EXP(B33))+1 -> -1.481375e-10 | E33: =A33-(C33/(C33-D33))*(A33-B33) -> 1.2611033 | F33: =E33^4-EXP(E33)+1 -> 0
A35: d. f(x)=(x^2)*(e^x)-1
A36: x1 | B36: x2 | C36: f(x1) | D36: f(x2) | E36: x3 | F36: f(x3)
A37: 0.5 | B37: 1 | C37: =A37^2*EXP(A37)-1 -> -0.58781968 | D37: =B37^2*EXP(B37)-1 -> 1.7182818 | E37: =A37-(C37/(C37-D37))*(A37-B37) -> 0.62744879 | F37: =E37^2*EXP(E37)-1 -> -0.26268323
A38: =B37 -> 1 | B38: =E37 -> 0.62744879 | C38: =A38^2*EXP(A38)-1 -> 1.7182818 | D38: =B38^2*EXP(B38)-1 -> -0.26268323 | E38: =A38-(C38/(C38-D38))*(A38-B38) -> 0.67685044 | F38: =E38^2*EXP(E38)-1 -> -0.098557877
A39: =B38 -> 0.62744879 | B39: =E38 -> 0.67685044 | C39: =A39^2*EXP(A39)-1 -> -0.26268323 | D39: =B39^2*EXP(B39)-1 -> -0.098557877 | E39: =A39-(C39/(C39-D39))*(A39-B39) -> 0.70651632 | F39: =E39^2*EXP(E39)-1 -> 0.011767059
A40: =B39 -> 0.67685044 | B40: =E39 -> 0.70651632 | C40: =A40^2*EXP(A40)-1 -> -0.098557877 | D40: =B40^2*EXP(B40)-1 -> 0.011767059 | E40: =A40-(C40/(C40-D40))*(A40-B40) -> 0.70335221 | F40: =E40^2*EXP(E40)-1 -> -0.00044269323
A41: =B40 -> 0.70651632 | B41: =E40 -> 0.70335221 | C41: =A41^2*EXP(A41)-1 -> 0.011767059 | D41: =B41^2*EXP(B41)-1 -> -0.00044269323 | E41: =A41-(C41/(C41-D41))*(A41-B41) -> 0.70346693 | F41: =E41^2*EXP(E41)-1 -> -1.8801413e-06
A42: =B41 -> 0.70335221 | B42: =E41 -> 0.70346693 | C42: =A42^2*EXP(A42)-1 -> -0.00044269323 | D42: =B42^2*EXP(B42)-1 -> -1.8801413e-06 | E42: =A42-(C42/(C42-D42))*(A42-B42) -> 0.70346742 | F42: =E42^2*EXP(E42)-1 -> 3.0235592e-10
A43: =B42 -> 0.70346693 | B43: =E42 -> 0.70346742 | C43: =A43^2*EXP(A43)-1 -> -1.8801413e-06 | D43: =B43^2*EXP(B43)-1 -> 3.0235592e-10 | E43: =A43-(C43/(C43-D43))*(A43-B43) -> 0.70346742 | F43: =E43^2*EXP(E43)-1 -> 0
A44: =B43 -> 0.70346742 | B44: =E43 -> 0.70346742 | C44: =A44^2*EXP(A44)-1 -> 3.0235592e-10 | D44: =B44^2*EXP(B44)-1 -> 0 | E44: =A44-(C44/(C44-D44))*(A44-B44) -> 0.70346742 | F44: =E44^2*EXP(E44)-1 -> 0

Sheet Sheet4
A1: Exercise 1.6 | C1: Newton's Method
A2: a. f(x)=x-x^(1/3)-2
A3: f'(x)=1-1/3*x^(-2/3)
A4: x | B4: f(x) | C4: f'(x)
A5: 3 | B5: =A5-A5^(1/3)-2 -> -0.44224957 | C5: =1-(1/3)*(A5^(-2/3)) -> 0.83975005
A6: =A5-(B5/C5) -> 3.5266443 | B6: =A6-A6^(1/3)-2 -> 0.0045067918 | C6: =1-(1/3)*(A6^(-2/3)) -> 0.85612976
A7: =A6-(B6/C6) -> 3.5213801 | B7: =A7-A7^(1/3)-2 -> 3.7714141e-07 | C7: =1-(1/3)*(A7^(-2/3)) -> 0.85598641
A8: =A7-(B7/C7) -> 3.5213797 | B8: =A8-A8^(1/3)-2 -> 0 | C8: =1-(1/3)*(A8^(-2/3)) -> 0.8559864
A9: =A8-(B8/C8) -> 3.5213797 | B9: =A9-A9^(1/3)-2 -> 0 | C9: =1-(1/3)*(A9^(-2/3)) -> 0.8559864
A10: =A9-(B9/C9) -> 3.5213797 | B10: =A10-A10^(1/3)-2 -> 0 | C10: =1-(1/3)*(A10^(-2/3)) -> 0.8559864
A13: b. f(x)=x*tan(x)-1
A14: f'(x)=x*sec^2(x)+tan(x)
A15: x | B15: f(x) | C15: f'(x)
A16: 1 | B16: =A16*TAN(A16)-1 -> 0.55740772 | C16: =A16*(_xlfn.SEC(A16))^2+TAN(A16) -> 4.9829265
A17: =A16-(B16/C16) -> 0.88813648 | B17: =A17*TAN(A17)-1 -> 0.092324626 | C17: =A17*(_xlfn.SEC(A17))^2+TAN(A17) -> 3.4614997
A18: =A17-(B17/C17) -> 0.86146462 | B18: =A18*TAN(A18)-1 -> 0.0036083668 | C18: =A18*(_xlfn.SEC(A18))^2+TAN(A18) -> 3.1956732
A19: =A18-(B18/C18) -> 0.86033548 | B19: =A19*TAN(A19)-1 -> 6.0127138e-06 | C19: =A19*(_xlfn.SEC(A19))^2+TAN(A19) -> 3.185031
A20: =A19-(B19/C19) -> 0.86033359 | B20: =A20*TAN(A20)-1 -> 1.6757484e-11 | C20: =A20*(_xlfn.SEC(A20))^2+TAN(A20) -> 3.1850133
A21: =A20-(B20/C20) -> 0.86033359 | B21: =A21*TAN(A21)-1 -> 0 | C21: =A21*(_xlfn.SEC(A21))^2+TAN(A21) -> 3.1850133
A24: c. f(x)=(x^4)-(e^x)+1 | D24: f'(x)=4x^3-e^x
A25: x | B25: f(x) | C25: f'(x)
A26: 1 | B26: =(A26^4)-EXP(A26)+1 -> -0.71828183 | C26: =4*A26^3-EXP(A26) -> 1.2817182
A27: =A26-(B26/C26) -> 1.5604054 | B27: =(A27^4)-EXP(A27)+1 -> 2.1678171 | C27: =4*A27^3-EXP(A27) -> 10.436756
A28: =A27-(B27/C27) -> 1.3526956 | B28: =(A28^4)-EXP(A28)+1 -> 0.48027678 | C28: =4*A28^3-EXP(A28) -> 6.0327325
A29: =A28-(B28/C28) -> 1.2730838 | B29: =(A29^4)-EXP(A29)+1 -> 0.054955153 | C29: =4*A29^3-EXP(A29) -> 4.6815123
A30: =A29-(B29/C29) -> 1.261345 | B30: =(A30^4)-EXP(A30)+1 -> 0.0010866592 | C30: =4*A30^3-EXP(A30) -> 4.4969889
A31: =A30-(B30/C30) -> 1.2611034 | B31: =(A31^4)-EXP(A31)+1 -> 4.5426662e-07 | C31: =4*A31^3-EXP(A31) -> 4.4932293
A32: =A31-(B31/C31) -> 1.2611033 | B32: =(A32^4)-EXP(A32)+1 -> 7.860379e-14 | C32: =4*A32^3-EXP(A32) -> 4.4932277
A34: d. f(x)=(x^2)*(e^x)-1 | D34: f'(x)=2x*(e^x)+(x^2)(e^x)
A35: x | B35: f(x) | C35: f'(x)
A36: 0.5 | B36: =(A36^2)*(EXP(A36))-1 -> -0.58781968 | C36: =2*(A36)*(EXP(A36))+(A36^2)*(EXP(A36)) -> 2.0609016
A37: =A36-(B36/C36) -> 0.78522453 | B37: =(A37^2)*(EXP(A37))-1 -> 0.35209247 | C37: =2*(A37)*(EXP(A37))+(A37^2)*(EXP(A37)) -> 4.795929
A38: =A37-(B37/C37) -> 0.71180967 | B38: =(A38^2)*(EXP(A38))-1 -> 0.032435126 | C38: =2*(A38)*(EXP(A38))+(A38^2)*(EXP(A38)) -> 3.9333093
A39: =A38-(B38/C38) -> 0.7035634 | B39: =(A39^2)*(EXP(A39))-1 -> 0.00036888402 | C39: =2*(A39)*(EXP(A39))+(A39^2)*(EXP(A39)) -> 3.8440895
A40: =A39-(B39/C39) -> 0.70346744 | B40: =(A40^2)*(EXP(A40))-1 -> 4.9399432e-08 | C40: =2*(A40)*(EXP(A40))+(A40^2)*(EXP(A40)) -> 3.84306
A41: =A40-(B40/C40) -> 0.70346742 | B41: =(A41^2)*(EXP(A41))-1 -> 0 | C41: =2*(A41)*(EXP(A41))+(A41^2)*(EXP(A41)) -> 3.8430599
